<?xml version="1.0" ?>
<robot name="arhex" xmlns:xacro="http://www.ros.org/wiki/xacro">

<xacro:include filename="$(find arhex_description)/urdf/materials.xacro" />
<xacro:include filename="$(find arhex_description)/urdf/arhex.trans" />
<xacro:include filename="$(find arhex_description)/urdf/arhex.gazebo" />
<link name="footprint" />
<link name="base_link">
  <inertial>
    <origin rpy="0 0 0" xyz="0.00026976113326567376 0.0 0.2"/>
    <mass value="3.703374358474152"/>
    <inertia ixx="0.020087" ixy="-0.0" ixz="-0.0" iyy="0.090417" iyz="0.0" izz="0.108396"/>
  </inertial>
  <visual>
    <origin rpy="0 0 0" xyz="0 0 0.2"/>
    <geometry>
      <mesh filename="package://arhex_description/meshes/base_link.stl" scale="0.001 0.001 0.001"/>
    </geometry>
    <material name="silver"/>
  </visual>
  <collision>
    <origin rpy="0 0 0" xyz="0 0 0.2"/>
    <geometry>
      <mesh filename="package://arhex_description/meshes/base_link.stl" scale="0.001 0.001 0.001"/>
    </geometry>
  </collision>
</link>
<joint name="base_joint" type="fixed">
  <parent link="footprint"/>
  <child link="base_link"/>
</joint>
<link name="torso_1">
  <inertial>
    <origin rpy="0 0 0" xyz="1.2212453270876722e-14 -0.0499832912360148 3.620232196793651e-05"/>
    <mass value="0.3736910404945874"/>
    <inertia ixx="0.000426" ixy="-0.0" ixz="-0.0" iyy="0.000229" iyz="-0.0" izz="0.000426"/>
  </inertial>
  <visual>
    <origin rpy="0 0 0" xyz="-0.12 -0.05 -0.0"/>
    <geometry>
      <mesh filename="package://arhex_description/meshes/torso_1.stl" scale="0.001 0.001 0.001"/>
    </geometry>
    <material name="silver"/>
  </visual>
  <collision>
    <origin rpy="0 0 0" xyz="-0.12 -0.05 -0.0"/>
    <geometry>
      <mesh filename="package://arhex_description/meshes/torso_1.stl" scale="0.001 0.001 0.001"/>
    </geometry>
  </collision>
</link>

<link name="shoulder_1">
  <inertial>
    <origin rpy="0 0 0" xyz="1.7208456881689926e-15 -0.004181551355216745 0.011286652343633782"/>
    <mass value="0.015935762832508082"/>
    <inertia ixx="2e-06" ixy="0.0" ixz="-0.0" iyy="2e-06" iyz="0.0" izz="2e-06"/>
  </inertial>
  <visual>
    <origin rpy="0 0 0" xyz="-0.12 -0.015 -0.035"/>
    <geometry>
      <mesh filename="package://arhex_description/meshes/shoulder_1.stl" scale="0.001 0.001 0.001"/>
    </geometry>
    <material name="silver"/>
  </visual>
  <collision>
    <origin rpy="0 0 0" xyz="-0.12 -0.015 -0.035"/>
    <geometry>
      <mesh filename="package://arhex_description/meshes/shoulder_1.stl" scale="0.001 0.001 0.001"/>
    </geometry>
  </collision>
</link>

<link name="upperarm_1">
  <inertial>
    <origin rpy="0 0 0" xyz="-3.3306690738754696e-16 0.0002781080914872648 0.13111538727151936"/>
    <mass value="0.23960543654925723"/>
    <inertia ixx="0.001291" ixy="-0.0" ixz="0.0" iyy="0.001291" iyz="8e-06" izz="3.6e-05"/>
  </inertial>
  <visual>
    <origin rpy="0 0 0" xyz="-0.12 -0.015 -0.0575"/>
    <geometry>
      <mesh filename="package://arhex_description/meshes/upperarm_1.stl" scale="0.001 0.001 0.001"/>
    </geometry>
    <material name="silver"/>
  </visual>
  <collision>
    <origin rpy="0 0 0" xyz="-0.12 -0.015 -0.0575"/>
    <geometry>
      <mesh filename="package://arhex_description/meshes/upperarm_1.stl" scale="0.001 0.001 0.001"/>
    </geometry>
  </collision>
</link>

<link name="forearm_1">
  <inertial>
    <origin rpy="0 0 0" xyz="8.743006318923108e-16 -0.014999999999999998 0.08527907512073357"/>
    <mass value="0.19017560846009895"/>
    <inertia ixx="0.000646" ixy="-0.0" ixz="0.0" iyy="0.000646" iyz="0.0" izz="2.9e-05"/>
  </inertial>
  <visual>
    <origin rpy="0 0 0" xyz="-0.12 -0.0 -0.3"/>
    <geometry>
      <mesh filename="package://arhex_description/meshes/forearm_1.stl" scale="0.001 0.001 0.001"/>
    </geometry>
    <material name="silver"/>
  </visual>
  <collision>
    <origin rpy="0 0 0" xyz="-0.12 -0.0 -0.3"/>
    <geometry>
      <mesh filename="package://arhex_description/meshes/forearm_1.stl" scale="0.001 0.001 0.001"/>
    </geometry>
  </collision>
</link>

<link name="wrist_1_1">
  <inertial>
    <origin rpy="0 0 0" xyz="-4.049678915818422e-08 0.0031269775133852505 0.010409122598549925"/>
    <mass value="0.01190830722415195"/>
    <inertia ixx="1e-06" ixy="-0.0" ixz="0.0" iyy="1e-06" iyz="-0.0" izz="1e-06"/>
  </inertial>
  <visual>
    <origin rpy="0 0 0" xyz="-0.12 0.015 -0.485"/>
    <geometry>
      <mesh filename="package://arhex_description/meshes/wrist_1_1.stl" scale="0.001 0.001 0.001"/>
    </geometry>
    <material name="silver"/>
  </visual>
  <collision>
    <origin rpy="0 0 0" xyz="-0.12 0.015 -0.485"/>
    <geometry>
      <mesh filename="package://arhex_description/meshes/wrist_1_1.stl" scale="0.001 0.001 0.001"/>
    </geometry>
  </collision>
</link>

<link name="wrist_2_1">
  <inertial>
    <origin rpy="0 0 0" xyz="-2.1699270158492823e-10 -0.003127028234251761 0.012090899904876884"/>
    <mass value="0.011908242587463931"/>
    <inertia ixx="1e-06" ixy="-0.0" ixz="-0.0" iyy="1e-06" iyz="-0.0" izz="1e-06"/>
  </inertial>
  <visual>
    <origin rpy="0 0 0" xyz="-0.12 0.015 -0.5075"/>
    <geometry>
      <mesh filename="package://arhex_description/meshes/wrist_2_1.stl" scale="0.001 0.001 0.001"/>
    </geometry>
    <material name="silver"/>
  </visual>
  <collision>
    <origin rpy="0 0 0" xyz="-0.12 0.015 -0.5075"/>
    <geometry>
      <mesh filename="package://arhex_description/meshes/wrist_2_1.stl" scale="0.001 0.001 0.001"/>
    </geometry>
  </collision>
</link>

<link name="palm_1">
  <inertial>
    <origin rpy="0 0 0" xyz="-1.7359919057824413e-11 0.0005267783635402104 0.003358343087855098"/>
    <mass value="0.004243048364927282"/>
    <inertia ixx="0.0" ixy="0.0" ixz="0.0" iyy="0.0" iyz="-0.0" izz="0.0"/>
  </inertial>
  <visual>
    <origin rpy="0 0 0" xyz="-0.12 0.015 -0.53"/>
    <geometry>
      <mesh filename="package://arhex_description/meshes/palm_1.stl" scale="0.001 0.001 0.001"/>
    </geometry>
    <material name="silver"/>
  </visual>
  <collision>
    <origin rpy="0 0 0" xyz="-0.12 0.015 -0.53"/>
    <geometry>
      <mesh filename="package://arhex_description/meshes/palm_1.stl" scale="0.001 0.001 0.001"/>
    </geometry>
  </collision>
</link>

<link name="right_endeffector_1">
  <inertial>
    <origin rpy="0 0 0" xyz="-0.0027212692793460447 -0.004999999999999978 0.0041762039773464155"/>
    <mass value="0.0006556991419596745"/>
    <inertia ixx="0.0" ixy="-0.0" ixz="0.0" iyy="0.0" iyz="0.0" izz="0.0"/>
  </inertial>
  <visual>
    <origin rpy="0 0 0" xyz="-0.1285 0.013 -0.5425"/>
    <geometry>
      <mesh filename="package://arhex_description/meshes/right_endeffector_1.stl" scale="0.001 0.001 0.001"/>
    </geometry>
    <material name="silver"/>
  </visual>
  <collision>
    <origin rpy="0 0 0" xyz="-0.1285 0.013 -0.5425"/>
    <geometry>
      <mesh filename="package://arhex_description/meshes/right_endeffector_1.stl" scale="0.001 0.001 0.001"/>
    </geometry>
  </collision>
</link>

<link name="left_endeffector_1">
  <inertial>
    <origin rpy="0 0 0" xyz="0.0027212657030671605 -0.004999999999999999 0.0041762039773463044"/>
    <mass value="0.0006556991419596745"/>
    <inertia ixx="0.0" ixy="0.0" ixz="-0.0" iyy="0.0" iyz="0.0" izz="0.0"/>
  </inertial>
  <visual>
    <origin rpy="0 0 0" xyz="-0.1115 0.013 -0.5425"/>
    <geometry>
      <mesh filename="package://arhex_description/meshes/left_endeffector_1.stl" scale="0.001 0.001 0.001"/>
    </geometry>
    <material name="silver"/>
  </visual>
  <collision>
    <origin rpy="0 0 0" xyz="-0.1115 0.013 -0.5425"/>
    <geometry>
      <mesh filename="package://arhex_description/meshes/left_endeffector_1.stl" scale="0.001 0.001 0.001"/>
    </geometry>
  </collision>
</link>

<link name="leg_FR_1">
  <inertial>
    <origin rpy="0 0 0" xyz="-0.0604811121285076 0.0075000000000000205 -0.09500000000000028"/>
    <mass value="0.024174555469373752"/>
    <inertia ixx="0.00011" ixy="0.0" ixz="0.0" iyy="0.00013" iyz="-0.0" izz="2.1e-05"/>
  </inertial>
  <visual>
    <origin rpy="0 0 0" xyz="-0.21 -0.102 -0.0"/>
    <geometry>
      <mesh filename="package://arhex_description/meshes/leg_FR_1.stl" scale="0.001 0.001 0.001"/>
    </geometry>
    <material name="silver"/>
  </visual>
  <collision>
    <origin rpy="0 0 0" xyz="-0.21 -0.102 -0.0"/>
    <geometry>
      <mesh filename="package://arhex_description/meshes/leg_FR_1.stl" scale="0.001 0.001 0.001"/>
    </geometry>
  </collision>
</link>

<link name="leg_MR_1">
  <inertial>
    <origin rpy="0 0 0" xyz="-0.06048111212850748 0.007499999999999868 -0.09500000000000028"/>
    <mass value="0.024174555469373752"/>
    <inertia ixx="0.00011" ixy="0.0" ixz="0.0" iyy="0.00013" iyz="0.0" izz="2.1e-05"/>
  </inertial>
  <visual>
    <origin rpy="0 0 0" xyz="-0.0 -0.117 -0.0"/>
    <geometry>
      <mesh filename="package://arhex_description/meshes/leg_MR_1.stl" scale="0.001 0.001 0.001"/>
    </geometry>
    <material name="silver"/>
  </visual>
  <collision>
    <origin rpy="0 0 0" xyz="-0.0 -0.117 -0.0"/>
    <geometry>
      <mesh filename="package://arhex_description/meshes/leg_MR_1.stl" scale="0.001 0.001 0.001"/>
    </geometry>
  </collision>
</link>

<link name="leg_RR_1">
  <inertial>
    <origin rpy="0 0 0" xyz="-0.06048111212850768 0.007499999999999993 -0.09500000000000028"/>
    <mass value="0.02417455546937379"/>
    <inertia ixx="0.00011" ixy="0.0" ixz="0.0" iyy="0.00013" iyz="-0.0" izz="2.1e-05"/>
  </inertial>
  <visual>
    <origin rpy="0 0 0" xyz="0.21 -0.102 -0.0"/>
    <geometry>
      <mesh filename="package://arhex_description/meshes/leg_RR_1.stl" scale="0.001 0.001 0.001"/>
    </geometry>
    <material name="silver"/>
  </visual>
  <collision>
    <origin rpy="0 0 0" xyz="0.21 -0.102 -0.0"/>
    <geometry>
      <mesh filename="package://arhex_description/meshes/leg_RR_1.stl" scale="0.001 0.001 0.001"/>
    </geometry>
  </collision>
</link>

<link name="leg_RL_1">
  <inertial>
    <origin rpy="0 0 0" xyz="-0.06048111212850768 -0.0075000000000000205 -0.09500000000000028"/>
    <mass value="0.02417455546937379"/>
    <inertia ixx="0.00011" ixy="0.0" ixz="0.0" iyy="0.00013" iyz="0.0" izz="2.1e-05"/>
  </inertial>
  <visual>
    <origin rpy="0 0 0" xyz="0.21 0.102 -0.0"/>
    <geometry>
      <mesh filename="package://arhex_description/meshes/leg_RL_1.stl" scale="0.001 0.001 0.001"/>
    </geometry>
    <material name="silver"/>
  </visual>
  <collision>
    <origin rpy="0 0 0" xyz="0.21 0.102 -0.0"/>
    <geometry>
      <mesh filename="package://arhex_description/meshes/leg_RL_1.stl" scale="0.001 0.001 0.001"/>
    </geometry>
  </collision>
</link>

<link name="leg_ML_1">
  <inertial>
    <origin rpy="0 0 0" xyz="-0.06048111212850748 -0.007499999999999882 -0.09500000000000028"/>
    <mass value="0.024174555469373752"/>
    <inertia ixx="0.00011" ixy="-0.0" ixz="0.0" iyy="0.00013" iyz="-0.0" izz="2.1e-05"/>
  </inertial>
  <visual>
    <origin rpy="0 0 0" xyz="-0.0 0.117 -0.0"/>
    <geometry>
      <mesh filename="package://arhex_description/meshes/leg_ML_1.stl" scale="0.001 0.001 0.001"/>
    </geometry>
    <material name="silver"/>
  </visual>
  <collision>
    <origin rpy="0 0 0" xyz="-0.0 0.117 -0.0"/>
    <geometry>
      <mesh filename="package://arhex_description/meshes/leg_ML_1.stl" scale="0.001 0.001 0.001"/>
    </geometry>
  </collision>
</link>

<link name="leg_FL_1">
  <inertial>
    <origin rpy="0 0 0" xyz="-0.0604811121285076 -0.007500000000000076 -0.09500000000000028"/>
    <mass value="0.024174555469373752"/>
    <inertia ixx="0.00011" ixy="-0.0" ixz="0.0" iyy="0.00013" iyz="0.0" izz="2.1e-05"/>
  </inertial>
  <visual>
    <origin rpy="0 0 0" xyz="-0.21 0.102 -0.0"/>
    <geometry>
      <mesh filename="package://arhex_description/meshes/leg_FL_1.stl" scale="0.001 0.001 0.001"/>
    </geometry>
    <material name="silver"/>
  </visual>
  <collision>
    <origin rpy="0 0 0" xyz="-0.21 0.102 -0.0"/>
    <geometry>
      <mesh filename="package://arhex_description/meshes/leg_FL_1.stl" scale="0.001 0.001 0.001"/>
    </geometry>
  </collision>
</link>

<joint name="torso" type="revolute">
  <origin rpy="0 0 0" xyz="0.12 0.05 0.2"/>
  <parent link="base_link"/>
  <child link="torso_1"/>
  <axis xyz="0.0 1.0 0.0"/>
  <limit effort="30" lower="-1.570796" upper="0.698132" velocity="4"/>
</joint>

<joint name="shoulder_1" type="revolute">
  <origin rpy="0 0 0" xyz="0.0 -0.035 0.035"/>
  <parent link="torso_1"/>
  <child link="shoulder_1"/>
  <axis xyz="0.0 0.0 1.0"/>
  <limit effort="30" lower="-1.570796" upper="1.570796" velocity="4"/>
</joint>

<joint name="shoulder_2" type="revolute">
  <origin rpy="0 0 0" xyz="0.0 0.0 0.0225"/>
  <parent link="shoulder_1"/>
  <child link="upperarm_1"/>
  <axis xyz="0.0 -1.0 0.0"/>
  <limit effort="30" lower="-1.570796" upper="1.570796" velocity="4"/>
</joint>

<joint name="elbow" type="revolute">
  <origin rpy="0 0 0" xyz="0.0 -0.015 0.2425"/>
  <parent link="upperarm_1"/>
  <child link="forearm_1"/>
  <axis xyz="0.0 1.0 0.0"/>
  <limit effort="30" lower="-3.141593" upper="0.0" velocity="4"/>
</joint>

<joint name="wrist_1" type="revolute">
  <origin rpy="0 0 0" xyz="0.0 -0.015 0.185"/>
  <parent link="forearm_1"/>
  <child link="wrist_1_1"/>
  <axis xyz="0.0 0.0 1.0"/>
  <limit effort="30" lower="-3.141593" upper="0.0" velocity="4"/>
</joint>

<joint name="wrist_2" type="revolute">
  <origin rpy="0 0 0" xyz="0.0 0.0 0.0225"/>
  <parent link="wrist_1_1"/>
  <child link="wrist_2_1"/>
  <axis xyz="0.0 1.0 0.0"/>
  <limit effort="30" lower="-1.570796" upper="1.570796" velocity="4"/>
</joint>

<joint name="wrist_3" type="revolute">
  <origin rpy="0 0 0" xyz="0.0 0.0 0.0225"/>
  <parent link="wrist_2_1"/>
  <child link="palm_1"/>
  <axis xyz="0.0 0.0 1.0"/>
  <limit effort="30" lower="-3.141593" upper="0.0" velocity="4"/>
</joint>

<joint name="ef_1" type="revolute">
  <origin rpy="0 0 0" xyz="0.0085 0.002 0.0125"/>
  <parent link="palm_1"/>
  <child link="right_endeffector_1"/>
  <axis xyz="0.0 1.0 0.0"/>
  <limit effort="30" lower="0.0" upper="1.308997" velocity="4"/>
</joint>

<joint name="ef_2" type="revolute">
  <origin rpy="0 0 0" xyz="-0.0085 0.002 0.0125"/>
  <parent link="palm_1"/>
  <child link="left_endeffector_1"/>
  <axis xyz="0.0 1.0 0.0"/>
  <limit effort="30" lower="-1.22173" upper="0.0" velocity="4"/>
</joint>

<joint name="L_FR" type="continuous">
  <origin rpy="0 0 0" xyz="0.21 0.102 0.2"/>
  <parent link="base_link"/>
  <child link="leg_FR_1"/>
  <axis xyz="0.0 1.0 0.0"/>
  <limit effort="30" velocity="4"/>
  <joint_properties damping="1.0" friction="1.0"/>
</joint>

<joint name="L_MR" type="continuous">
  <origin rpy="0 0 0" xyz="0.0 0.117 0.2"/>
  <parent link="base_link"/>
  <child link="leg_MR_1"/>
  <axis xyz="0.0 1.0 0.0"/>
  <limit effort="30" velocity="4"/>
  <joint_properties damping="1.0" friction="1.0"/>
</joint>

<joint name="L_RR" type="continuous">
  <origin rpy="0 0 0" xyz="-0.21 0.102 0.2"/>
  <parent link="base_link"/>
  <child link="leg_RR_1"/>
  <axis xyz="0.0 1.0 0.0"/>
  <limit effort="30" velocity="4"/>
  <joint_properties damping="1.0" friction="1.0"/>
</joint>

<joint name="L_RL" type="continuous">
  <origin rpy="0 0 0" xyz="-0.21 -0.102 0.2"/>
  <parent link="base_link"/>
  <child link="leg_RL_1"/>
  <axis xyz="0.0 -1.0 0.0"/>
  <limit effort="30" velocity="4"/>
  <joint_properties damping="1.0" friction="1.0"/>
</joint>

<joint name="L_ML" type="continuous">
  <origin rpy="0 0 0" xyz="0.0 -0.117 0.2"/>
  <parent link="base_link"/>
  <child link="leg_ML_1"/>
  <axis xyz="0.0 -1.0 0.0"/>
  <limit effort="30" velocity="4"/>
  <joint_properties damping="1.0" friction="1.0"/>
</joint>

<joint name="L_FL" type="continuous">
  <origin rpy="0 0 0" xyz="0.21 -0.102 0.2"/>
  <parent link="base_link"/>
  <child link="leg_FL_1"/>
  <axis xyz="0.0 -1.0 0.0"/>
  <limit effort="30" velocity="4"/>
  <joint_properties damping="1.0" friction="1.0"/>
</joint>

</robot>
